<sdf version='1.6'>
  <model name='poke_arm_main'>
    <link name='poke_base_link'>
      <pose frame=''>0 0 0 0 -0 0</pose>
      <inertial>
        <pose frame=''>0 0 0.025 0 -0 0</pose>
        <mass>0.01</mass>
        <inertia>
          <ixx>0.0001</ixx>
          <ixy>0</ixy>
          <ixz>0</ixz>
          <iyy>0.0001</iyy>
          <iyz>0</iyz>
          <izz>0.0001</izz>
        </inertia>
      </inertial>
      <collision name='poke_base_link_fixed_joint_lump__baseMount_link_collision'>
        <pose frame=''>0 0 0.025 0 -0 0</pose>
        <geometry>
          <cylinder>
            <length>0.05</length>
            <radius>0.05</radius>
          </cylinder>
        </geometry>
      </collision>
      <visual name='poke_base_link_fixed_joint_lump__baseMount_link_visual'>
        <pose frame=''>0 0 0.025 0 -0 0</pose>
        <geometry>
          <cylinder>
            <length>0.05</length>
            <radius>0.05</radius>
          </cylinder>
        </geometry>
      </visual>
    </link>
    <joint name='poke_base_joint' type='fixed'>
      <child>poke_base_link</child>
      <parent>world</parent>
    </joint>
    <link name='p0_link'>
      <pose frame=''>0 0 0.095 0 -0 0</pose>
      <inertial>
        <pose frame=''>0 0 0.1 0 -0 0</pose>
        <mass>0.01</mass>
        <inertia>
          <ixx>0.0001</ixx>
          <ixy>0</ixy>
          <ixz>0</ixz>
          <iyy>0.0001</iyy>
          <iyz>0</iyz>
          <izz>0.0001</izz>
        </inertia>
      </inertial>
      <collision name='p0_link_fixed_joint_lump__p0_joint_c_collision'>
        <pose frame=''>0 0 0 1.57079 -0 0</pose>
        <geometry>
          <cylinder>
            <length>0.06</length>
            <radius>0.045</radius>
          </cylinder>
        </geometry>
      </collision>
      <collision name='p0_link_fixed_joint_lump__p0_segmentL_c_collision_1'>
        <pose frame=''>0 0 0.1 0 -0 0</pose>
        <geometry>
          <cylinder>
            <length>0.2</length>
            <radius>0.03</radius>
          </cylinder>
        </geometry>
      </collision>
      <visual name='p0_link_fixed_joint_lump__p0_joint_v_visual'>
        <pose frame=''>0 0 0 1.57079 -0 0</pose>
        <geometry>
          <cylinder>
            <length>0.06</length>
            <radius>0.045</radius>
          </cylinder>
        </geometry>
      </visual>
      <visual name='p0_link_fixed_joint_lump__p0_segmentL_v_visual_1'>
        <pose frame=''>0 0 0.1 0 -0 0</pose>
        <geometry>
          <cylinder>
            <length>0.2</length>
            <radius>0.03</radius>
          </cylinder>
        </geometry>
      </visual>
    </link>
    <joint name='p0_joint' type='revolute'>
      <child>p0_link</child>
      <parent>poke_base_link</parent>
      <axis>
        <xyz>0 1 0</xyz>
        <limit>
          <lower>-3.14159</lower>
          <upper>3.14159</upper>
          <effort>100</effort>
          <velocity>5</velocity>
        </limit>
        <dynamics>
          <spring_reference>0</spring_reference>
          <spring_stiffness>0</spring_stiffness>
        </dynamics>
        <use_parent_model_frame>1</use_parent_model_frame>
      </axis>
    </joint>
    <link name='p1_link'>
      <pose frame=''>0 0 0.34 0 -0 0</pose>
      <inertial>
        <pose frame=''>0 0 0.1 0 -0 0</pose>
        <mass>0.01</mass>
        <inertia>
          <ixx>0.0001</ixx>
          <ixy>0</ixy>
          <ixz>0</ixz>
          <iyy>0.0001</iyy>
          <iyz>0</iyz>
          <izz>0.0001</izz>
        </inertia>
      </inertial>
      <collision name='p1_link_fixed_joint_lump__p1_joint_c_collision'>
        <pose frame=''>0 0 0 1.57079 -0 0</pose>
        <geometry>
          <cylinder>
            <length>0.06</length>
            <radius>0.045</radius>
          </cylinder>
        </geometry>
      </collision>
      <collision name='p1_link_fixed_joint_lump__p1_segmentL_c_collision_1'>
        <pose frame=''>0 0 0.1 0 -0 0</pose>
        <geometry>
          <cylinder>
            <length>0.2</length>
            <radius>0.03</radius>
          </cylinder>
        </geometry>
      </collision>
      <visual name='p1_link_fixed_joint_lump__p1_joint_v_visual'>
        <pose frame=''>0 0 0 1.57079 -0 0</pose>
        <geometry>
          <cylinder>
            <length>0.06</length>
            <radius>0.045</radius>
          </cylinder>
        </geometry>
      </visual>
      <visual name='p1_link_fixed_joint_lump__p1_segmentL_v_visual_1'>
        <pose frame=''>0 0 0.1 0 -0 0</pose>
        <geometry>
          <cylinder>
            <length>0.2</length>
            <radius>0.03</radius>
          </cylinder>
        </geometry>
      </visual>
    </link>
    <joint name='p1_joint' type='revolute'>
      <child>p1_link</child>
      <parent>p0_link</parent>
      <axis>
        <xyz>0 1 0</xyz>
        <limit>
          <lower>-3.14159</lower>
          <upper>3.14159</upper>
          <effort>100</effort>
          <velocity>5</velocity>
        </limit>
        <dynamics>
          <spring_reference>0</spring_reference>
          <spring_stiffness>0</spring_stiffness>
        </dynamics>
        <use_parent_model_frame>1</use_parent_model_frame>
      </axis>
    </joint>
    <link name='p2_link'>
      <pose frame=''>0 0 0.585 0 -0 0</pose>
      <inertial>
        <pose frame=''>0 0 0.05 0 -0 0</pose>
        <mass>0.01</mass>
        <inertia>
          <ixx>0.0001</ixx>
          <ixy>0</ixy>
          <ixz>0</ixz>
          <iyy>0.0001</iyy>
          <iyz>0</iyz>
          <izz>0.0001</izz>
        </inertia>
      </inertial>
      <collision name='p2_link_fixed_joint_lump__p2_joint_c_collision'>
        <pose frame=''>0 0 0 1.57079 -0 0</pose>
        <geometry>
          <cylinder>
            <length>0.06</length>
            <radius>0.045</radius>
          </cylinder>
        </geometry>
      </collision>
      <collision name='p2_link_fixed_joint_lump__p2_segmentS_c_collision_1'>
        <pose frame=''>0 0 0.05 0 -0 0</pose>
        <geometry>
          <cylinder>
            <length>0.1</length>
            <radius>0.03</radius>
          </cylinder>
        </geometry>
      </collision>
      <visual name='p2_link_fixed_joint_lump__p2_joint_v_visual'>
        <pose frame=''>0 0 0 1.57079 -0 0</pose>
        <geometry>
          <cylinder>
            <length>0.06</length>
            <radius>0.045</radius>
          </cylinder>
        </geometry>
      </visual>
      <visual name='p2_link_fixed_joint_lump__p2_segmentS_v_visual_1'>
        <pose frame=''>0 0 0.05 0 -0 0</pose>
        <geometry>
          <cylinder>
            <length>0.1</length>
            <radius>0.03</radius>
          </cylinder>
        </geometry>
      </visual>
    </link>
    <joint name='p2_joint' type='revolute'>
      <child>p2_link</child>
      <parent>p1_link</parent>
      <axis>
        <xyz>0 1 0</xyz>
        <limit>
          <lower>-3.14159</lower>
          <upper>3.14159</upper>
          <effort>100</effort>
          <velocity>5</velocity>
        </limit>
        <dynamics>
          <spring_reference>0</spring_reference>
          <spring_stiffness>0</spring_stiffness>
        </dynamics>
        <use_parent_model_frame>1</use_parent_model_frame>
      </axis>
    </joint>
    <link name='p3_link'>
      <pose frame=''>0 0 0.7075 0 -0 0</pose>
      <inertial>
        <pose frame=''>0 0 0.018 0 -0 0</pose>
        <mass>0.02</mass>
        <inertia>
          <ixx>0.00010748</ixx>
          <ixy>0</ixy>
          <ixz>0</ixz>
          <iyy>0.00010748</iyy>
          <iyz>0</iyz>
          <izz>0.000101</izz>
        </inertia>
      </inertial>
      <collision name='p3_link_fixed_joint_lump__p3_cSeg_c_collision'>
        <pose frame=''>0 0 0 0 -0 0</pose>
        <geometry>
          <box>
            <size>0.045 0.045 0.045</size>
          </box>
        </geometry>
      </collision>
      <collision name='p3_link_fixed_joint_lump__gripper_frame_cp_collision_1'>
        <pose frame=''>0 0 0.036 3.14159 -1.57079 3.14159</pose>
        <geometry>
          <box>
            <size>0.0225 0.03375 0.045</size>
          </box>
        </geometry>
      </collision>
      <visual name='p3_link_fixed_joint_lump__p3_cSeg_v_visual'>
        <pose frame=''>0 0 0 0 -0 0</pose>
        <geometry>
          <box>
            <size>0.045 0.045 0.045</size>
          </box>
        </geometry>
      </visual>
      <visual name='p3_link_fixed_joint_lump__gripper_frame_cp_visual_1'>
        <pose frame=''>0 0 0.036 3.14159 -1.57079 3.14159</pose>
        <geometry>
          <box>
            <size>0.0225 0.03375 0.045</size>
          </box>
        </geometry>
      </visual>
    </link>
    <joint name='p3_joint' type='revolute'>
      <child>p3_link</child>
      <parent>p2_link</parent>
      <axis>
        <xyz>0 0 1</xyz>
        <limit>
          <lower>-1e+16</lower>
          <upper>1e+16</upper>
        </limit>
        <dynamics>
          <spring_reference>0</spring_reference>
          <spring_stiffness>0</spring_stiffness>
        </dynamics>
        <use_parent_model_frame>1</use_parent_model_frame>
      </axis>
    </joint>
    <link name='gripper_link_1'>
      <pose frame=''>0 0 0.8075 0 -0 0</pose>
      <inertial>
        <pose frame=''>0 0 0.075 0 -0 0</pose>
        <mass>0.2</mass>
        <inertia>
          <ixx>0.000541667</ixx>
          <ixy>0</ixy>
          <ixz>0</ixz>
          <iyy>0.000541667</iyy>
          <iyz>0</iyz>
          <izz>0.000333333</izz>
        </inertia>
      </inertial>
      <collision name='gripper_link_1_collision_collision'>
        <pose frame=''>0.025 0 0.025 0 -0 0</pose>
        <geometry>
          <box>
            <size>0.025 0.1 0.15</size>
          </box>
        </geometry>
        <surface>
          <contact>
            <ode/>
          </contact>
          <friction>
            <ode/>
          </friction>
        </surface>
      </collision>
      <visual name='gripper_link_1_visual'>
        <pose frame=''>0.025 0 0.025 0 -0 0</pose>
        <geometry>
          <box>
            <size>0.025 0.1 0.15</size>
          </box>
        </geometry>
        <material>
          <script>
            <uri>__default__</uri>
            <name>__default__</name>
          </script>
        </material>
      </visual>
      <gravity>1</gravity>
      <velocity_decay/>
      <sensor name='gripper_1_sensor' type='contact'>
        <plugin name='gripper_1_sensor' filename='libgazebo_ros_bumper.so'>
          <bumperTopicName>gripper_1_vals</bumperTopicName>
          <frameName>world</frameName>
          <alwayson>1</alwayson>
          <updaterate>100.0</updaterate>
        </plugin>
        <always_on>1</always_on>
        <update_rate>1000</update_rate>
        <contact>
          <collision>gripper_link_1_collision_collision</collision>
          <topic>__default_topic__</topic>
        </contact>
      </sensor>
    </link>
    <joint name='gripper_1' type='prismatic'>
      <child>gripper_link_1</child>
      <parent>p3_link</parent>
      <axis>
        <xyz>1 0 0</xyz>
        <limit>
          <lower>0.025</lower>
          <upper>0.5</upper>
          <effort>30</effort>
          <velocity>1</velocity>
        </limit>
        <dynamics>
          <spring_reference>0</spring_reference>
          <spring_stiffness>0</spring_stiffness>
        </dynamics>
        <use_parent_model_frame>1</use_parent_model_frame>
      </axis>
    </joint>
    <link name='gripper_link_2'>
      <pose frame=''>0 0 0.8075 0 -0 0</pose>
      <inertial>
        <pose frame=''>0 0 0.075 0 -0 0</pose>
        <mass>0.2</mass>
        <inertia>
          <ixx>0.000541667</ixx>
          <ixy>0</ixy>
          <ixz>0</ixz>
          <iyy>0.000541667</iyy>
          <iyz>0</iyz>
          <izz>0.000333333</izz>
        </inertia>
      </inertial>
      <collision name='gripper_link_2_collision_collision'>
        <pose frame=''>-0.025 0 0.025 0 -0 0</pose>
        <geometry>
          <box>
            <size>0.025 0.1 0.15</size>
          </box>
        </geometry>
        <surface>
          <contact>
            <ode/>
          </contact>
          <friction>
            <ode/>
          </friction>
        </surface>
      </collision>
      <visual name='gripper_link_2_visual'>
        <pose frame=''>-0.025 0 0.025 0 -0 0</pose>
        <geometry>
          <box>
            <size>0.025 0.1 0.15</size>
          </box>
        </geometry>
        <material>
          <script>
            <uri>__default__</uri>
            <name>__default__</name>
          </script>
        </material>
      </visual>
      <gravity>1</gravity>
      <velocity_decay/>
      <sensor name='gripper_2_sensor' type='contact'>
        <plugin name='gripper_2_sensor' filename='libgazebo_ros_bumper.so'>
          <bumperTopicName>gripper_2_vals</bumperTopicName>
          <frameName>world</frameName>
          <alwayson>1</alwayson>
          <updaterate>100.0</updaterate>
        </plugin>
        <always_on>1</always_on>
        <update_rate>1000</update_rate>
        <contact>
          <collision>gripper_link_2_collision_collision</collision>
          <topic>__default_topic__</topic>
        </contact>
      </sensor>
    </link>
    <joint name='gripper_2' type='prismatic'>
      <child>gripper_link_2</child>
      <parent>p3_link</parent>
      <axis>
        <xyz>1 0 0</xyz>
        <limit>
          <lower>-0.5</lower>
          <upper>-0.025</upper>
          <effort>30</effort>
          <velocity>1</velocity>
        </limit>
        <dynamics>
          <spring_reference>0</spring_reference>
          <spring_stiffness>0</spring_stiffness>
        </dynamics>
        <use_parent_model_frame>1</use_parent_model_frame>
      </axis>
    </joint>
    <plugin name='gazebo_ros_control' filename='libgazebo_ros_control.so'>
      <robotSimType>gazebo_ros_control/DefaultRobotHWSim</robotSimType>
      <robotNamespace>/</robotNamespace>
    </plugin>
    <static>0</static>
    <plugin name='joint_state_publisher' filename='libgazebo_ros_joint_state_publisher.so'>
      <jointName>p0_joint, p1_joint, p2_joint, p3_joint, gripper_1, gripper_2</jointName>
    </plugin>
  </model>
</sdf>
