<?xml version="1.0" encoding="utf-8"?>
<!-- =================================================================================== -->
<!-- |    This document was autogenerated by xacro from poke.urdf.xacro                | -->
<!-- |    EDITING THIS FILE BY HAND IS NOT RECOMMENDED                                 | -->
<!-- =================================================================================== -->
<!-- URDF xacro of the poke arm. Use this file for creation/modification of urdf or moveit config.
  Use the following command to generate the urdf file:  $ rosrun xacro xacro.py poke_old.xacro -o poke.urdf
                                    To check the urdf:  $ check_urdf poke.urdf
                                   Export urdf to pdf:  $ urdf_to_graphiz poke.urdf
-->
<robot name="poke_arm_main" xmlns:controller="http://playerstage.sourceforge.net/gazebo/xmlschema/#controller" xmlns:interface="http://playerstage.sourceforge.net/gazebo/xmlschema/#interface" xmlns:sensor="http://playerstage.sourceforge.net/gazebo/xmlschema/#sensor">
  <!--finger length-->
  <!--finger length-->
  <!-- ros_control plugin -->
  <gazebo>
    <plugin filename="libgazebo_ros_control.so" name="gazebo_ros_control">
      <robotSimType>gazebo_ros_control/DefaultRobotHWSim</robotSimType>
    </plugin>
  </gazebo>
  <gazebo>
    <plugin filename="libgazebo_ros_joint_state_publisher.so" name="joint_state_publisher">
      <jointName>p0_joint, p1_joint, p2_joint, p3_joint, gripper_1, gripper_2</jointName>
    </plugin>
  </gazebo>
  <!-- Gazebo colors -->
  <gazebo reference="baseMount">
    <material>Gazebo/Grey</material>
  </gazebo>
  <gazebo reference="p0">
    <material>Gazebo/Orange</material>
  </gazebo>
  <gazebo reference="p1">
    <material>Gazebo/Orange</material>
  </gazebo>
  <gazebo reference="p2">
    <material>Gazebo/Orange</material>
  </gazebo>
  <gazebo reference="p3">
    <material>Gazebo/Green</material>
  </gazebo>
  <material name="white">
    <color rgba="0.87 0.90 0.87 1.0"/>
  </material>
  <material name="black">
    <color rgba="0.0 0.0 0.0 1.0"/>
  </material>
  <material name="green">
    <color rgba="0.22 0.32 0.14 1.0"/>
  </material>
  <material name="grey">
    <color rgba="0.2 0.2 0.2 1.0"/>
  </material>
  <material name="orange">
    <color rgba="1.0 0.423529411765 0.0392156862745 1.0"/>
  </material>
  <!--
    For simulating only the arm, we'll use "world" as the link name.
    For using it on the turtlebot, use "base_link" as the link name.
    -->
  <!-- As we don't have here a turtlebot, add a base_link link as its location reference -->
  <link name="world"/>
  <!-- base_link -->
  <link name="poke_base_link"/>
  <joint name="poke_base_joint" type="fixed">
    <origin xyz="0 0 0"/>
    <parent link="world"/>
    <child link="poke_base_link"/>
  </joint>
  <joint name="baseMount_joint" type="fixed">
    <origin rpy="0 0 0" xyz="0 0 0"/>
    <parent link="poke_base_link"/>
    <child link="baseMount_link"/>
  </joint>
  <link name="baseMount_link">
    <inertial>
      <mass value="0.01"/>
      <origin xyz="0 0 0.025"/>
      <inertia ixx="0.0001" ixy="0" ixz="0" iyy="0.0001" iyz="0" izz="0.0001"/>
    </inertial>
    <visual>
      <origin xyz="0 0 0.025"/>
      <geometry>
        <cylinder length="0.05" radius="0.05"/>
      </geometry>
      <material name="grey"/>
    </visual>
    <collision>
      <origin xyz="0 0 0.025"/>
      <geometry>
        <cylinder length="0.05" radius="0.05"/>
      </geometry>
    </collision>
  </link>
  <joint name="p0_joint" type="revolute">
    <origin rpy="0 0 0" xyz="0.0 0.0 0.095"/>
    <parent link="baseMount_link"/>
    <child link="p0_link"/>
    <axis xyz="0 1 0"/>
    <limit effort="100" lower="-1.04719666667" upper="1.5079632" velocity="5"/>
    <!--origin rpy="0 0 0" xyz="0.0 0.0 ${l1+jr}" /-->
  </joint>
  <link name="p0_link">
    <inertial>
      <mass value="0.01"/>
      <origin rpy="0 0 0" xyz="0 0 0.1"/>
      <inertia ixx="0.0001" ixy="0" ixz="0" iyy="0.0001" iyz="0" izz="0.0001"/>
      <origin rpy="0 0 0" xyz="0 0 0.1"/>
    </inertial>
    <!-- Visual for segment joint -->
    <visual name="p0_joint_v">
      <geometry>
        <cylinder length="0.06" radius="0.045"/>
      </geometry>
      <origin rpy="1.570795 0 0" xyz="0 0 0"/>
      <material name="orange"/>
    </visual>
    <collision name="p0_joint_c">
      <geometry>
        <cylinder length="0.06" radius="0.045"/>
      </geometry>
      <origin rpy="1.570795 0 0" xyz="0 0 0"/>
    </collision>
    <!-- Visual for main segment -->
    <visual name="p0_segmentL_v">
      <geometry>
        <cylinder length="0.2" radius="0.03"/>
      </geometry>
      <origin rpy="0 0 0" xyz="0 0 0.1"/>
      <material name="orange"/>
    </visual>
    <collision name="p0_segmentL_c">
      <geometry>
        <cylinder length="0.2" radius="0.03"/>
      </geometry>
      <origin rpy="0 0 0" xyz="0 0 0.1"/>
    </collision>
  </link>
  <joint name="p1_joint" type="revolute">
    <origin rpy="0 0 0" xyz="0.0 0.0 0.245"/>
    <parent link="p0_link"/>
    <child link="p1_link"/>
    <axis xyz="0 1 0"/>
    <limit effort="100" lower="0" upper="2.09439333333" velocity="5"/>
    <!--origin rpy="0 0 0" xyz="0.0 0.0 ${l1+jr}" /-->
  </joint>
  <link name="p1_link">
    <inertial>
      <mass value="0.01"/>
      <origin rpy="0 0 0" xyz="0 0 0.1"/>
      <inertia ixx="0.0001" ixy="0" ixz="0" iyy="0.0001" iyz="0" izz="0.0001"/>
      <origin rpy="0 0 0" xyz="0 0 0.1"/>
    </inertial>
    <!-- Visual for segment joint -->
    <visual name="p1_joint_v">
      <geometry>
        <cylinder length="0.06" radius="0.045"/>
      </geometry>
      <origin rpy="1.570795 0 0" xyz="0 0 0"/>
      <material name="orange"/>
    </visual>
    <collision name="p1_joint_c">
      <geometry>
        <cylinder length="0.06" radius="0.045"/>
      </geometry>
      <origin rpy="1.570795 0 0" xyz="0 0 0"/>
    </collision>
    <!-- Visual for main segment -->
    <visual name="p1_segmentL_v">
      <geometry>
        <cylinder length="0.2" radius="0.03"/>
      </geometry>
      <origin rpy="0 0 0" xyz="0 0 0.1"/>
      <material name="orange"/>
    </visual>
    <collision name="p1_segmentL_c">
      <geometry>
        <cylinder length="0.2" radius="0.03"/>
      </geometry>
      <origin rpy="0 0 0" xyz="0 0 0.1"/>
    </collision>
  </link>
  <joint name="p2_joint" type="revolute">
    <parent link="p1_link"/>
    <child link="p2_link"/>
    <axis xyz="0 1 0"/>
    <limit effort="100" lower="-2.09439333333" upper="2.09439333333" velocity="5"/>
    <origin rpy="0 0 0" xyz="0.0 0.0 0.245"/>
  </joint>
  <link name="p2_link">
    <inertial>
      <mass value="0.01"/>
      <inertia ixx="0.0001" ixy="0" ixz="0" iyy="0.0001" iyz="0" izz="0.0001"/>
      <origin rpy="0 0 0" xyz="0 0 0.05"/>
    </inertial>
    <!-- Visual for segment joint -->
    <visual name="p2_joint_v">
      <geometry>
        <cylinder length="0.06" radius="0.045"/>
      </geometry>
      <origin rpy="1.570795 0 0" xyz="0 0 0"/>
      <material name="orange"/>
    </visual>
    <collision name="p2_joint_c">
      <geometry>
        <cylinder length="0.06" radius="0.045"/>
      </geometry>
      <origin rpy="1.570795 0 0" xyz="0 0 0"/>
    </collision>
    <!-- Visual for main segment -->
    <visual name="p2_segmentS_v">
      <geometry>
        <cylinder length="0.1" radius="0.03"/>
      </geometry>
      <origin rpy="0 0 0" xyz="0 0 0.05"/>
      <material name="orange"/>
    </visual>
    <collision name="p2_segmentS_c">
      <geometry>
        <cylinder length="0.1" radius="0.03"/>
      </geometry>
      <origin rpy="0 0 0" xyz="0 0 0.05"/>
    </collision>
  </link>
  <joint name="p3_joint" type="continuous">
    <axis xyz="0 0 1"/>
    <parent link="p2_link"/>
    <child link="p3_link"/>
    <origin rpy="0 0 0" xyz="0.0 0.0 0.1225"/>
  </joint>
  <link name="p3_link">
    <inertial>
      <mass value="0.01"/>
      <origin rpy="0 0 0" xyz="0 0 0"/>
      <inertia ixx="0.0001" ixy="0" ixz="0" iyy="0.0001" iyz="0" izz="0.0001"/>
    </inertial>
    <!-- Visual for segment -->
    <visual name="p3_cSeg_v">
      <geometry>
        <box size="0.045 0.045 0.045"/>
      </geometry>
      <material name="green"/>
      <origin rpy="0 0 0" xyz="0 0 0"/>
    </visual>
    <collision name="p3_cSeg_c">
      <geometry>
        <box size="0.045 0.045 0.045"/>
      </geometry>
      <origin rpy="0 0 0" xyz="0 0 0"/>
    </collision>
  </link>
  <joint name="gripper_1" type="prismatic">
    <origin rpy="0.0 0.0 0.0" xyz="0.0 0.0 0.1"/>
    <axis xyz="0 0 0"/>
    <parent link="p3_link"/>
    <child link="gripper_link_1"/>
    <limit effort="10.0" lower="0.025" upper="0.5" velocity="1.0"/>
    <dynamics damping="1.0" stiffness="1000.0"/>
  </joint>
  <joint name="gripper_2" type="prismatic">
    <origin rpy="0.0 0.0 0.0" xyz="0.0 0.0 0.1"/>
    <parent link="p3_link"/>
    <child link="gripper_link_2"/>
    <axis xyz="0.0 0.0 0.0"/>
    <limit effort="10.0" lower="-0.5" upper="-0.025" velocity="1.0"/>
    <dynamics damping="1.0" stiffness="1000.0"/>
  </joint>
  <joint name="gripper_frame_joint" type="fixed">
    <!--origin xyz="0.0 0.0 ${radius_52*2 + length_62/2 + 0.01}" rpy="0.0 0.0 0.0"/-->
    <origin rpy="0.0 0.0 0.0" xyz="0.0 0.0 0.0"/>
    <parent link="p3_link"/>
    <child link="gripper_frame_cp"/>
    <axis xyz="0.0 0.0 0.0"/>
  </joint>
  <link name="gripper_link_1">
    <inertial>
      <origin rpy="0 0 0" xyz="0 0 0.075"/>
      <mass value="0.02"/>
      <inertia ixx="0.000541666666667" ixy="0.0" ixz="0.0" iyy="0.000541666666667" iyz="0.0" izz="0.000333333333333"/>
    </inertial>
    <visual>
      <origin rpy="0.0 0.0 0.0" xyz="0.0 0.0 0.025"/>
      <geometry>
        <box size="0.025 0.1 0.15"/>
      </geometry>
      <material name="Grey"/>
    </visual>
    <collision>
      <origin rpy="0.0 0.0 0.0" xyz="0.0 0.0 0.025"/>
      <geometry>
        <box size="0.025 0.1 0.15"/>
      </geometry>
    </collision>
  </link>
  <link name="gripper_link_2">
    <inertial>
      <origin rpy="0 0 0" xyz="0 0 0.075"/>
      <mass value="0.02"/>
      <inertia ixx="0.000541666666667" ixy="0.0" ixz="0.0" iyy="0.000541666666667" iyz="0.0" izz="0.000333333333333"/>
    </inertial>
    <visual>
      <origin rpy="0.0 0.0 0.0" xyz="0.0 0.0 0.025"/>
      <geometry>
        <box size="0.025 0.1 0.15"/>
      </geometry>
      <material name="Grey"/>
    </visual>
    <collision>
      <origin rpy="0.0 0.0 0.0" xyz="0.0 0.0 0.025"/>
      <geometry>
        <box size="0.025 0.1 0.15"/>
      </geometry>
    </collision>
  </link>
  <link name="gripper_frame_cp">
    <inertial>
      <mass value="0.01" />
      <origin xyz="0 0 0" rpy="0 0 0" />
      <inertia ixx="1e-6" ixy="0" ixz="0" iyy="1e-6" iyz="0" izz="1e-6" />
      </inertial>
    <visual>
      <origin rpy="0.0 0.5 0.0" xyz="0.0 0.0 0.0"/>
      <geometry>
        <box size="0.1 0.05 0.05"/>
      </geometry>
      <material name="Grey"/>
    </visual>
    <collision>
      <origin rpy="0.0 0.0 0.0" xyz="0.0 0.0 0.0"/>
      <geometry>
        <box size="0.1 0.05 0.05"/>
      </geometry>
    </collision>
  </link>
  <transmission name="p0_joint_tran">
    <type>transmission_interface/SimpleTransmission</type>
    <joint name="p0_joint">
      <hardwareInterface>PositionJointInterface</hardwareInterface>
    </joint>
    <actuator name="p0_joint_motor">
      <hardwareInterface>PositionJointInterface</hardwareInterface>
      <mechanicalReduction>1</mechanicalReduction>
    </actuator>
  </transmission>
  <transmission name="p1_joint_tran">
    <type>transmission_interface/SimpleTransmission</type>
    <joint name="p1_joint">
      <hardwareInterface>PositionJointInterface</hardwareInterface>
    </joint>
    <actuator name="p1_joint_motor">
      <hardwareInterface>PositionJointInterface</hardwareInterface>
      <mechanicalReduction>1</mechanicalReduction>
    </actuator>
  </transmission>
  <transmission name="p2_joint_tran">
    <type>transmission_interface/SimpleTransmission</type>
    <joint name="p2_joint">
      <hardwareInterface>PositionJointInterface</hardwareInterface>
    </joint>
    <actuator name="p2_joint_motor">
      <hardwareInterface>PositionJointInterface</hardwareInterface>
      <mechanicalReduction>1</mechanicalReduction>
    </actuator>
  </transmission>
  <transmission name="p3_joint_tran">
    <type>transmission_interface/SimpleTransmission</type>
    <joint name="p3_joint">
      <hardwareInterface>PositionJointInterface</hardwareInterface>
    </joint>
    <actuator name="p3_joint_motor">
      <hardwareInterface>PositionJointInterface</hardwareInterface>
      <mechanicalReduction>1</mechanicalReduction>
    </actuator>
  </transmission>
  <transmission name="gripper_1_tran">
    <type>transmission_interface/SimpleTransmission</type>
    <joint name="gripper_1">
      <hardwareInterface>PositionJointInterface</hardwareInterface>
    </joint>
    <actuator name="gripper_1_motor">
      <hardwareInterface>PositionJointInterface</hardwareInterface>
      <mechanicalReduction>1</mechanicalReduction>
    </actuator>
  </transmission>
  <transmission name="gripper_2_tran">
    <type>transmission_interface/SimpleTransmission</type>
    <joint name="gripper_2">
      <hardwareInterface>PositionJointInterface</hardwareInterface>
    </joint>
    <actuator name="gripper_2_motor">
      <hardwareInterface>PositionJointInterface</hardwareInterface>
      <mechanicalReduction>1</mechanicalReduction>
    </actuator>
  </transmission>
  <gazebo reference="gripper_link_1">
    <bounceThreshold>0.0</bounceThreshold>
    <mu1>100</mu1>
    <mu2>100</mu2>
    <kp>1000.0</kp>
    <kd>1.0</kd>
    <minDepth>0.001</minDepth>
    <maxVel>0.0</maxVel>
    <torsional>
        <ode>
            <coefficient>1000</coefficient>
            <slip>0</slip>
        </ode>
    </torsional>
  </gazebo>
  <gazebo reference="gripper_link_2">
    <bounceThreshold>0.0</bounceThreshold>
    <mu1>100</mu1>
    <mu2>100</mu2>
    <kp>1000.0</kp>
    <kd>1.0</kd>
    <minDepth>0.001</minDepth>
    <maxVel>0.0</maxVel>
    <torsional>
        <ode>
            <coefficient>1000</coefficient>
            <slip>0</slip>
        </ode>
    </torsional>
  </gazebo>
</robot>
